Workbook
Name IQ_CH: 110000
Name IQ_CQ: 5000
Name IQ_CY: 10000
Name IQ_DAILY: 500000
Name IQ_FH: 100000
Name IQ_FQ: 500
Name IQ_FY: 1000
Name IQ_LTM: 2000
Name IQ_MONTH: 15000
Name IQ_NTM: 6000
Name IQ_WEEK: 50000
Name IQ_YTD: 3000

Sheet DCF
B1: PepsiCo DCF Valuation
B2: ='PepsiCo-IS'!A2 -> (in USD million except per Share Data)
B3: Valuation Date | C3: 44104
B5: Choose Discounting | E5: 2
AF6: Mid Year Discounting
C7: ='PepsiCo-IS'!I3 -> 6 | D7: ='PepsiCo-IS'!K3 -> 12 | E7: ='PepsiCo-IS'!L3 -> 12 | F7: ='PepsiCo-IS'!M3 -> 12 | G7: ='PepsiCo-IS'!N3 -> 12 | AF7: Year End Discounting
B8: Date of cash flows | C8: ='PepsiCo-IS'!I4 -> 44196 | D8: ='PepsiCo-IS'!K4 -> 44561 | E8: ='PepsiCo-IS'!L4 -> 44926 | F8: ='PepsiCo-IS'!M4 -> 45291 | G8: ='PepsiCo-IS'!N4 -> 45657
B10: EBIT | C10: ='PepsiCo-IS'!I22 -> 6280.1228 | D10: ='PepsiCo-IS'!K22 -> 11541.677 | E10: ='PepsiCo-IS'!L22 -> 12019.53 | F10: ='PepsiCo-IS'!M22 -> 12523.531 | G10: ='PepsiCo-IS'!N22 -> 13055.351
B11: Tax Rate | C11: ='PepsiCo-IS'!I68 -> 0.21485287 | D11: ='PepsiCo-IS'!K68 -> 0.22619544 | E11: ='PepsiCo-IS'!L68 -> 0.24079696 | F11: ='PepsiCo-IS'!M68 -> 0.25539848 | G11: ='PepsiCo-IS'!N68 -> 0.27 | H11: 0.27
B12: Tax expense | C12: =-C10*C11 -> -1349.3024 | D12: =-D10*D11 -> -2610.6748 | E12: =-E10*E11 -> -2894.2663 | F12: =-F10*F11 -> -3198.4909 | G12: =-G10*G11 -> -3524.9447
B13: NOPAT | C13: =C12+C10 -> 4930.8204 | D13: =D12+D10 -> 8931.0025 | E13: =E12+E10 -> 9125.2637 | F13: =F12+F10 -> 9325.0404 | G13: =G12+G10 -> 9530.4062
B14: Add: Depreciation and amortisation | C14: ='PepsiCo-CFS'!B8 -> 1267.4709 | D14: ='PepsiCo-CFS'!C8 -> 2632.5475 | E14: ='PepsiCo-CFS'!D8 -> 2733.997 | F14: ='PepsiCo-CFS'!E8 -> 2841.4158 | G14: ='PepsiCo-CFS'!F8 -> 2955.1632 | I14: All from CFS
B15: Add/Less: (Increase)/ Decrease in net working capital | C15: =SUM('PepsiCo-CFS'!B11:B14) -> 2918.1112 | D15: =SUM('PepsiCo-CFS'!C11:C14) -> 374.66333 | E15: =SUM('PepsiCo-CFS'!D11:D14) -> 146.34667 | F15: =SUM('PepsiCo-CFS'!E11:E14) -> 154.46044 | G15: =SUM('PepsiCo-CFS'!F11:F14) -> 163.08688
B16: Less: Capital expenditure | C16: ='PepsiCo-CFS'!B19 -> -2348.5197 | D16: ='PepsiCo-CFS'!C19 -> -2100.0133 | E16: ='PepsiCo-CFS'!D19 -> -3479.2286 | F16: ='PepsiCo-CFS'!E19 -> -3634.7676 | G16: ='PepsiCo-CFS'!F19 -> -3799.3231
B17: Debt free cash flow (Free Cash Flows to Firm) | C17: =SUM(C13:C16) -> 6767.8828 | D17: =SUM(D13:D16) -> 9838.2 | E17: =SUM(E13:E16) -> 8526.3788 | F17: =SUM(F13:F16) -> 8686.149 | G17: =SUM(G13:G16) -> 8849.3331 | H17: =G17*(1+D29) -> 9027.2047
A18: =WACC!N8 -> 0.052190726 | B18: Discount rate (%)
B19: Full Period or Partial Period | C19: =_xlfn.DAYS(C8,$C$3)/30/C7 -> 0.51111111 | D19: 1 | E19: 1 | F19: 1 | G19: 1
B20: Discounting Period-Year End | C20: =_xlfn.DAYS(C8,$C$3)/30/12 -> 0.25555556 | D20: =_xlfn.DAYS(D8,$C$3)/30/12 -> 1.2694444 | E20: =_xlfn.DAYS(E8,$C$3)/30/12 -> 2.2833333 | F20: =_xlfn.DAYS(F8,$C$3)/30/12 -> 3.2972222 | G20: =_xlfn.DAYS(G8,$C$3)/30/12 -> 4.3138889 | I20: Assumed CF is coming at end of period | M20: 2
B21: Discounting Period-Mid Year | C21: =C20/2 -> 0.12777778 | D21: =D20-0.5 -> 0.76944444 | E21: =E20-0.5 -> 1.7833333 | F21: =F20-0.5 -> 2.7972222 | G21: =G20-0.5 -> 3.8138889 | I21: Assumed CF is coming at middle of period | M21: 1
B22: Present value factor- END year discounting | C22: =(1+$A$18)^C20 -> 1.0130861 | D22: =(1+$A$18)^D20 -> 1.0667133 | E22: =(1+$A$18)^E20 -> 1.1231792 | F22: =(1+$A$18)^F20 -> 1.182634 | G22: =(1+$A$18)^G20 -> 1.2454121 | I22: Denominator
B23: Present value factor- MID year discounting | C23: =(1+$A$18)^C21 -> 1.0065218 | D23: =(1+$A$18)^D21 -> 1.0399213 | E23: =(1+$A$18)^E21 -> 1.094969 | F23: =(1+$A$18)^F21 -> 1.1529305 | G23: =(1+$A$18)^G21 -> 1.2141319
B24: Present value debt free cash flow | C24: =IF($E$5=2,C17*C19/C22,C17/C23) -> 3414.4581 | D24: =IF($E$5=2,D17*D19/D22,D17/D23) -> 9222.9095 | E24: =IF($E$5=2,E17*E19/E22,E17/E23) -> 7591.29 | F24: =IF($E$5=2,F17*F19/F22,F17/F23) -> 7344.7479 | G24: =IF($E$5=2,G17*G19/G22,G17/G23) -> 7105.546
B26: Present value for explicit period (4.5 Years) | G26: =SUM(C24:G24) -> 34678.952
J27: WACC
B28: Terminal value (for after 4.5 years) | D28: Gordon growth | I28: =D40 -> 164.16919 | J28: 0.045 | K28: =J28+0.25% -> 0.0475 | L28: =K28+0.25% -> 0.05 | M28: =L28+0.25% -> 0.0525 | N28: =M28+0.25% -> 0.055 | O28: =N28+0.25% -> 0.0575 | P28: =O28+0.25% -> 0.06 | Q28: =P28+0.25% -> 0.0625 | R28: =Q28+0.25% -> 0.065
B29: Long Term Growth Rate | D29: 0.0201 | E29: Close to US GDP Growth rate | H29: LTGR | I29: 0.01 | J29: 153.99954 | K29: 142.22178 | L29: 131.91634 | M29: 122.8234 | N29: 114.74086 | O29: 107.5092 | P29: 101.00077 | Q29: 95.112264 | R29: 89.759136
B30: Terminal Value | D30: =H17/(A18-D29) -> 281302.6 | E30: Discount sitting at 4.5 years | I30: =I29+0.25% -> 0.0125 | J30: 166.13945 | K30: 152.66005 | L30: 140.97796 | M30: 130.75618 | N30: 121.737 | O30: 113.72 | P30: 106.54692 | Q30: 100.09119 | R30: 94.250315
B31: Present Value of TV | D31: =D30/CHOOSE(E5,G23,G22) -> 225871.09 | E31: Present Value of Remaining period | I31: =I30+0.25% -> 0.015 | J31: 180.30267 | K31: 164.7042 | L31: 151.33409 | M31: 139.74666 | N31: 129.60766 | O31: 120.66147 | P31: 112.70931 | Q31: 105.59421 | R31: 99.190612
B32: DCF Value of Firm / Operating Business Enterprise Value | D32: =D31+G26 -> 260550.05 | E32: Operating worth only | I32: =I31+0.25% -> 0.0175 | J32: 197.04102 | K32: 178.75572 | L32: 163.28348 | M32: 150.0215 | N32: 138.52773 | O32: 128.47064 | P32: 119.59668 | Q32: 111.70868 | R32: 104.65094
B33: Add: Non Operating Assets | D33: ='PepsiCo-BS'!E17+'PepsiCo-BS'!E6 -> 2911 | I33: =I32+0.25% -> 0.02 | J33: 217.12704 | K33: 195.36205 | L33: 177.22442 | M33: 161.87708 | N33: 148.72211 | O33: 137.32102 | P33: 127.34498 | Q33: 118.54249 | R33: 110.71797
B34: Total Value of Firm | D34: =SUM(D32:D33) -> 263461.05 | I34: =I33+0.25% -> 0.0225 | J34: 241.67663 | K34: 215.28965 | L34: 193.70009 | M34: 175.7086 | N34: 160.48485 | O34: 147.43575 | P34: 136.12638 | Q34: 126.23054 | R34: 117.49877
B35: Less: Gross Debt & Debt Equivalents | D35: ='PepsiCo-BS'!E23+'PepsiCo-BS'!E27 -> 44978 | I35: =I34+0.25% -> 0.025 | J35: 272.36361 | K35: 239.6456 | L35: 213.47089 | M35: 192.05493 | N35: 174.20804 | O35: 159.10659 | P35: 146.16227 | Q35: 134.94365 | R35: 125.12717
B36: Add: Cash | D36: ='PepsiCo-BS'!E5 -> 8927 | I36: =I35+0.25% -> 0.0275 | J36: 311.81829 | K36: 270.09055 | L36: 237.6352 | M36: 211.67053 | N36: 190.42636 | O36: 172.72257 | P36: 157.74214 | Q36: 144.9015 | R36: 133.77269
B37: Less: Non Controling Interest | D37: ='PepsiCo-BS'!E41 -> 96 | I37: =I36+0.25% -> 0.03 | J37: 364.42454 | K37: 309.23405 | L37: 267.84059 | M37: 235.64516 | N37: 209.88835 | O37: 188.81418 | P37: 171.25199 | Q37: 156.39132 | R37: 143.65328
B38: DCF value of Common Equity | D38: =D34-D35+D36-D37 -> 227314.05
B39: No. of shares o/s-Diluted | D39: =1384632842/1000000 -> 1384.6328 | E39: Not Weigthed average. Exact Shares on that day
B40: DCF value per share | D40: =D38/D39 -> 164.16919
J41: WACC
B42: Terminal Value | D42: Exit Multiple Method | I42: =D55 -> 131.02483 | J42: =J28 -> 0.045 | K42: =K28 -> 0.0475 | L42: =L28 -> 0.05 | M42: =M28 -> 0.0525 | N42: =N28 -> 0.055 | O42: =O28 -> 0.0575 | P42: =P28 -> 0.06 | Q42: =Q28 -> 0.0625 | R42: =R28 -> 0.065
B43: LTM EV/EBITDA | D43: 14 | E43: Time Sensitive multiple | H43: Exit Multiple | I43: 11 | J43: 106.66223 | K43: 105.4345 | L43: 104.22183 | M43: 103.02401 | N43: 101.8408 | O43: 100.67201 | P43: 99.517414 | Q43: 98.376809 | R43: 97.249991
...

Sheet DCF Summary
B2: PepsiCo DCF Valuation — Summary of Steps
B3: (in USD million except per-share data). Walkthrough of how the model gets from forecasts to value per share.
B5: PART A — BUILDING THE FORECAST (the supporting sheets)
B6: Step | C6: What happens | D6: Where
B7: 1. Revenue | C7: Start with revenue, broken into 7 segments. Forecast organic growth and strip out special/one-off items after reconciling them to the filings. | D7: Revenue Segments
B8: 2. Income Statement | C8: Forecast each P&L line as a % of sales, EXCEPT schedule-driven lines (interest, depreciation, amortisation) which come from the asset/debt schedules. | D8: PepsiCo-IS
B9: 3. Fixed Assets / Net Block | C9: From history, back out PPE turnover, depreciation rate and amortisation rate. For forecast years: use PPE turnover × sales to size required PPE, then derive depreciation and net additions (capex). Link forecast depreciation & amortisation back into the I/S. | D9: Fixed Assets Schedule
B10: 4. Cash Flow – CFO | C10: Start from net income, add back D&A and stock-based comp (projected as a % of SG&A), then layer in changes in operating working capital from the balance sheet. | D10: PepsiCo-CFS / PepsiCo-BS
B11: 5. Cash Flow – CFI | C11: Capital expenditure — the additions to tangible and intangible assets from the Fixed Assets Schedule, carried in with a negative sign. | D11: PepsiCo-CFS
B12: 6. Cash Flow – CFF | C12: Financing items (debt movements, dividends, buybacks). Debt detail is captured in the Debt Schedule. | D12: PepsiCo-CFS / Debt Schedule
B14: PART B — THE DCF ENGINE (the DCF sheet)
B15: Step | C15: What happens | D15: Live value
B16: 7. Build FCFF | C16: For each period: EBIT → less tax = NOPAT; add back D&A; add/less change in net working capital; less capex = Debt-Free Cash Flow (Free Cash Flow to Firm). | D16: see DCF rows 10–17
B17: 8. Discount rate (WACC) | C17: Discount at WACC = weight×cost of debt + weight×cost of equity. Cost of equity via CAPM (risk-free + bottom-up beta × ERP). | D17: =WACC!N8 -> 0.052190726
B18: 9. Discount each period | C18: Apply a present-value factor to each period's FCFF (toggle for year-end vs. mid-year discounting), then sum the discounted explicit-period cash flows. | D18: =DCF!G26 -> 34678.952
B19: 10. Terminal value | C19: Gordon growth: final-year FCFF grown at the long-term rate, capitalised by (WACC − g), then discounted back to today. | D19: =DCF!D29 -> 0.0201
B20: 11. Enterprise value | C20: PV of explicit-period FCFF + PV of terminal value = operating enterprise value. | D20: =DCF!D32 -> 260550.05
B21: 12. Bridge to equity | C21: Add non-operating assets; less gross debt & equivalents; add cash; less non-controlling interest = equity value. | D21: =DCF!D38 -> 227314.05
B22: 13. Value per share | C22: Divide equity value by diluted shares outstanding (exact shares on the valuation date, not weighted average). | D22: =DCF!D40 -> 164.16919
B23: 14. Sensitivity | C23: Two-way data table flexing WACC against long-term growth rate to show the range of value per share. | D23: DCF I28:N37
B25: HEADLINE RESULT
B26: DCF value per share | C26: =DCF!D40 -> 164.16919
B27: Implied equity value ($mm) | C27: =DCF!D38 -> 227314.05
B28: Operating enterprise value ($mm) | C28: =DCF!D32 -> 260550.05
B29: WACC / Long-term growth | C29: =TEXT(WACC!N8,"0.0%")&" / "&TEXT(DCF!D29,"0.0%") -> 5.2% / 2.0%

Sheet WACC
B1: PepsiCo WACC Calculation
B2: ='PepsiCo-IS'!A2 -> (in USD million except per Share Data)
D3: 1
B4: Cost of equity | F4: Cost of debt | J4: Weighted average cost of capital
B5: Particulars | C5: Notes | D5: Value | F5: Particulars | G5: Notes | H5: Value | J5: Particulars | K5: Weight | L5: Particulars | M5: Cost | N5: Value
B6: Risk-free rate (%) | C6: Average of YTD | D6: 0.009 | F6: Debt borrowing rate (%) | G6: Rating Based | H6: =D6+D9+0.98% -> 0.0188 | J6: Debt (%) | K6: =D24 -> 0.18440559 | L6: Cost of debt (%) | M6: =H8 -> 0.013724 | N6: =M6*K6 -> 0.0025307824
B7: Beta | C7: =IF(D3=1,B24,B25) -> Bottoms Up beta | D7: =CHOOSE(D3,H24,H25) -> 0.86336171 | F7: Expected income tax rate (%) | G7: Marginal | H7: =DCF!H11 -> 0.27 | J7: Equity (%) | K7: =E24 -> 0.81559441 | L7: Cost of equity (%) | M7: =D10 -> 0.060888039 | N7: =M7*K7 -> 0.049659944
B8: Equity market risk premium (%) | C8: Damodaran ERP | D8: 0.0601 | F8: After-tax cost of debt (%) | H8: =H6*(1-H7) -> 0.013724 | J8: WACC | N8: =SUM(N6:N7) -> 0.052190726
B9: Additional risk premium (%) | D9: 0 | F9: Source: Calculation | J9: Source: Calculation
B10: Cost of equity capital (%) | D10: =D6+D7*D8 -> 0.060888039
B11: Source: Calculation
B14: Calculation of beta
B15: Particulars | C15: Equity beta | D15: D/(D+E) (last three years) | E15: E/(D+E) (last three years) | F15: Tax rate (%) | G15: Unlevered beta | H15: Relevered beta | I15: R sq
B16: Bottom-up | K16: Peers method
B17: ='Beta Calculation'!H5 -> Coca Cola | C17: ='Beta Calculation'!I5 -> 0.90249372 | D17: =AVERAGE($C$32:$C$34)/(AVERAGE($C$32:$C$34)+AVERAGE($F$32:$F$34)) -> 0.20245408 | E17: =1-D17 -> 0.79754592 | F17: =AVERAGE($G$32:$G$34) -> 0.27 | G17: =C17*(E17/(D17*(1-F17)+E17)) -> 0.76140031 | I17: ='Beta Calculation'!J5 -> 0.59193544 | K17: Step 1 | L17: Calculate Levered beta of peer group
B18: ='Beta Calculation'!H10 -> Kraft Heinz | C18: ='Beta Calculation'!I10 -> 0.79741099 | D18: =AVERAGE($C$37:$C$39)/(AVERAGE($C$37:$C$39)+AVERAGE($F$37:$F$39)) -> 0.3821413 | E18: =1-D18 -> 0.6178587 | F18: =AVERAGE($G$37:$G$39) -> 0.27 | G18: =C18*(E18/(D18*(1-F18)+E18)) -> 0.54937033 | I18: ='Beta Calculation'!J10 -> 0.24858799 | K18: Step 2 | L18: unlever beta of peer group companies in 1 using historical capital structure | Q18: = | R18: levBeta*[ Equity / (Equity + Debt(1-t) ]
B19: ='Beta Calculation'!H11 -> Mondelez | C19: ='Beta Calculation'!I11 -> 0.75717638 | D19: =AVERAGE($C$42:$C$44)/(AVERAGE($C$42:$C$44)+AVERAGE($F$42:$F$44)) -> 0.2189331 | E19: =1-D19 -> 0.7810669 | F19: =AVERAGE($G$42:$G$44) -> 0.27 | G19: =C19*(E19/(D19*(1-F19)+E19)) -> 0.62856086 | I19: ='Beta Calculation'!J11 -> 0.51678726 | K19: Step 3 | L19: calc. industry avg of unlevered beta
B20: ='Beta Calculation'!H12 -> Monster Beverage | C20: ='Beta Calculation'!I12 -> 1.0248664 | D20: =AVERAGE($C$47:$C$49)/(AVERAGE($C$47:$C$49)+AVERAGE($F$47:$F$49)) -> 0 | E20: =1-D20 -> 1 | F20: =AVERAGE($G$52:$G$54) -> 0.27 | G20: =C20*(E20/(D20*(1-F20)+E20)) -> 1.0248664 | I20: ='Beta Calculation'!J12 -> 0.48482729 | K20: Step 4 | L20: calc beta of target company by levering the unlevered using the target structure | Q20: = | R20: unlever* [ Equity + Debt(1-t) / Equity ]
F21: Industry Average | G21: =AVERAGE(G17:G20) -> 0.74104947
F22: This is average business risk of the industry
B23: Beta Calculation for Target Co
A24: 1 | B24: Bottoms Up beta | D24: =AVERAGE(C52:C54)/(AVERAGE(C52:C54)+AVERAGE(F52:F54)) -> 0.18440559 | E24: =1-D24 -> 0.81559441 | F24: =AVERAGE(G52:G54) -> 0.27 | G24: =G21 -> 0.74104947 | H24: =G24 * (E24 + D24*(1-F24))/E24 -> 0.86336171
A25: 2 | B25: Regression beta | C25: ='Beta Calculation'!I4 -> 0.7773082 | D25: =D24 -> 0.18440559 | E25: =E24 -> 0.81559441 | F25: =F24 -> 0.27 | G25: Unlevered beta | H25: =C25 -> 0.7773082
B29: Calculation of Capital Structure of Peer Group Companies
C30: Debt | D30: Equity
B31: =B17 -> Coca Cola | D31: Share Price | E31: Shares O/S | F31: M.Cap | G31: Tax Rate
B32: 44008 | C32: =9423+5181+37729 -> 52333 | D32: 43.22 | E32: =4295438919/10^6 -> 4295.4389 | F32: =D32*E32 -> 185648.87 | G32: 0.27
B33: 43644 | C33: =13030+2749+29296 -> 45075 | D33: 48.9 | E33: =4276027437/10^6 -> 4276.0274 | F33: =D33*E33 -> 209097.74 | G33: 0.27
B34: 43280 | C34: =14715+4023+28063 -> 46801 | D34: 40.76 | E34: =4252922447/10^6 -> 4252.9224 | F34: =D34*E34 -> 173349.12 | G34: 0.27
B36: =B18 -> Kraft Heinz
B37: 44009 | C37: =6+757+28097 -> 28860 | D37: 30.9 | E37: =1222578592/10^6 -> 1222.5786 | F37: =D37*E37 -> 37777.678 | G37: 0.27
B38: 43645 | C38: =1+1298+29832 -> 31131 | D38: 31.04 | E38: =1219991425/10^6 -> 1219.9914 | F38: =D38*E38 -> 37868.534 | G38: 0.27
B39: 43281 | C39: =34+2754+31380 -> 34168 | D39: 62.82 | E39: =1219248231/10^6 -> 1219.2482 | F39: =D39*E39 -> 76593.174 | G39: 0.27
B41: =B19 -> Mondelez
B42: 44012 | C42: =2755+945+16004+479 -> 20183 | D42: 51.13 | E42: =1428338344/10^6 -> 1428.3383 | F42: =D42*E42 -> 73030.94 | G42: 0.27
B43: 43646 | C43: =3780+3675+11764 -> 19219 | D43: 53.9 | E43: =1442150501/10^6 -> 1442.1505 | F43: =D43*E43 -> 77731.912 | G43: 0.27
B44: 43281 | C44: =4074+780+14857 -> 19711 | D44: 41 | E44: =1466560999/10^6 -> 1466.561 | F44: =D44*E44 -> 60129.001 | G44: 0.27
B46: =B20 -> Monster Beverage
B47: 44012 | C47: 0 | D47: 69.32 | E47: =527396445/10^6 -> 527.39644 | F47: =D47*E47 -> 36559.122 | G47: 0.27
B48: 43646 | C48: 0 | D48: 63.83 | E48: =544879342/10^6 -> 544.87934 | F48: =D48*E48 -> 34779.648 | G48: 0.27
...

Sheet STEP BY STEP
C4: FORMAT where 3.5 years of data already available | I4: Till 13th June 2020
C6: Start with Revenue
D7: Break down revenue (in this case into 7 segments)
D8: Forcast organic growth and ignore special items after reconciling them from the financial reports
C10: Go down the I/S forecasting each item as a % of sales EXCEPT Schedule related lines like interest/ammortization/depr expense
C12: Move to net block Schedule
D13: For previous years to get PPE Turnover(for addition of PPE which justifies sales growth) and Depr rate
E14: Get opening and closing and depr from reports
E15: Get depreciation
E16: back calculate depr then depr rate and PPE Turnover
E17: Do same for ammort and get ammortization rate | J17: But here intangible does not support sales so turnover NOT calculated so how do we get ? WE ASSUME NO NET ADDITION (which happen through acq and merg)
D18: For Forcast years
E19: Use PPE Turnover and sales to get required PPE | J19: This is BEFORE Depr
E20: You can now get depr from depr rate and ppe and net addition from opening and PPE ( so two tasks after previous step)
AH21: Kd | AI21: PRE TAX COST OF DEBT | AL21: Current Cost of Issuing new long term debt ,not historical interest rates ,since WACC is used for future CF discounting
E22: Now link the forcasted depr expenses to I/S | J22: In this case the depr expense is split into Depr expense and Coporate depr and amort(yes I know amort in depr) exp | U22: Use historical ratio to forcast and back calculate split | Z22: Don’t forget /2 for 6 months | AI22: 3 ways | AR22: But if current and not historical then what if earlier 6% and now 10%? How do we realize the advantage
E23: For ammortizable assets directly ammortize the opening balance after assuming 0 new addition and link to I/S | AI23: 1 | AJ23: Recent Debt issued by company | AS23: the 4% saved over the periods will be discounted and reflected in MARKET VALUE OF DEBT ( earlier 100M but saved 4M say over 5 years so now MV of Debt is now 100-17.5 = 82.5
AI24: 2 | AJ24: Rating based default spread (Country + Company) + Risk Free rate
AI25: 3 | AJ25: Current Bond Yeild on Companys Debt Given they trade on the market
AK26: The price will change due to demand and YTM will converge to the current debt interest rate
C27: Leave Debt Schedule for now and move to CashFlowStatement | AL27: (if debt interest rate is higher why would I invest in company bond -> Price drop of bond -> YTM increase to match
AL28: (if bond YTM is higher why would I invest in Debt Funds -> Price increase of bond -> YTM decreases to match
C29: CashFlowStatement
D30: CFO | M30: Interest COST here only as not added back after taking NI (NI already inclused interest as a cost)
E31: Start from netIncome import from I/S
E32: add back depr and ammort | AH32: T | AI32: TAX RATE
E33: for share based compensation (which is to be added back since it’s a non cash expese) project it as a % of SG&A from previous years from I/S and then import it in CFS | AI33: Always marginal Rate which is Taxed on the NEXT unit of earnings | AP33: WACC is forward looking
E34: Change in operating assets will come from B/S | J34: Move to B/S for now for 4 items | AI34: NOT average effective rate of Tax
E37: B/S Working Balance for CFO only (rest later) | AH37: D/V | AI37: Weightage of debt
F38: Accounts reciavble, Inventories, Prepaid expenses are Operating current assets | AI38: Debt includes all INTEREST BEARING liabilities (st+lt+capital leases)
F39: Accounts payable and other current liabetes is Operating current Liabilities | N39: the whole group IS SPLIT INTO 2 OPERATING AND NON OPERATING | AI39: includes Asset DEFECIT for employee benefit obligation | AO39: Pension Obligation > Assets to fund Obligation | AT39: Underfunded Pension Liability treated as liability
AI40: includes Operating leases if capitalized | AM40: It represents fixed contractual payment over a long term period of financing. So very similar to borrowing treated as liability
F41: Project these 4 items through DPO DSO DIO and %age of sales (for prepaid expenses)
F42: Link them first to the top of B/S where it actually is supposed to be | M42: For acc payable you need to first input in the split area where non operating part is STILL TO BE PROJECTED and then back to the main b/s but right now only Operating is used so youre gucci | AI42: TARGET CAPITAL STRUCTURE USED NOT CURRENT | AO42: Forward looking
F43: THEN calculate CHANGES IN B/S ITEMS in CFO | M43: Here just do subtraction from previous period (6month - 1year allowed, makes sense)
AI44: Market value of debt used which depends on current interest rate | AP44: Because investors want required return demanded TODAY
F45: CFO READY
D47: CFI | AH47: Rf
E48: Only one item there i.e. Capex | AI48: Country bond rates + moodys default spread according to country | AQ48: if govt bond rate not there . GDP growth can act as good proxy
E49: Already projected in Fixed Asset Schedule (ADDITION OF ASSETS of BOTH TANGIBLE AND INTANGIBLE but here will come with a negative sign) | S49: Although addition of intangible was assumed to be zero | AI49: 10/20/30 year chosen depending on the DCF forecast period
...

Sheet Beta Calculation
B2: Competitors List as per PepsiCo Filing | H2: Beta calculation
B3: Comeptitor Name | E3: Geography | F3: M.Cap (bn USD) | H3: Name | I3: Beta | J3: R sq
A4: 1 | B4: The Coca-Cola Company | E4: USA | F4: 210 | H4: =B19 -> PepsiCo | I4: =_xlfn.COVARIANCE.P($C$22:$C$178,$U$22:$U$178)/_xlfn.VAR.P($U$22:$U$178) -> 0.7773082 | J4: =RSQ($C$22:$C$178,$U$22:$U$178) -> 0.52038993
A5: 2 | B5: Campbell Soup Company | E5: USA | F5: 14.6 | H5: =D19 -> Coca Cola | I5: =_xlfn.COVARIANCE.P($E$22:$E$178,$U$22:$U$178)/_xlfn.VAR.P($U$22:$U$178) -> 0.90249372 | J5: =RSQ($E$22:$E$178,$U$22:$U$178) -> 0.59193544
A6: 3 | B6: Conagra Brands | E6: USA | F6: 18 | H6: =F19 -> Campbell | I6: =_xlfn.COVARIANCE.P($G$22:$G$178,$U$22:$U$178)/_xlfn.VAR.P($U$22:$U$178) -> 0.3010841 | J6: =RSQ($G$22:$G$178,$U$22:$U$178) -> 0.042397392 | K6: Not enough Explained by market | L6: Ignored in Bottom up Beta Calculation
A7: 4 | B7: Kellogg Company | E7: USA | F7: 22.3 | H7: =H19 -> Conagra | I7: =_xlfn.COVARIANCE.P($I$22:$I$178,$U$22:$U$178)/_xlfn.VAR.P($U$22:$U$178) -> 0.61515834 | J7: =RSQ($I$22:$I$178,$U$22:$U$178) -> 0.13915576
A8: 5 | B8: Keurig Dr Pepper | E8: USA | F8: 39.4 | H8: =J19 -> Kellogg | I8: =_xlfn.COVARIANCE.P($K$22:$K$178,$U$22:$U$178)/_xlfn.VAR.P($U$22:$U$178) -> 0.4788202 | J8: =RSQ($K$22:$K$178,$U$22:$U$178) -> 0.17266424
A9: 6 | B9: The Kraft Heinz Company | E9: USA | F9: 37.5 | H9: =L19 -> Keurig Dr Pepper | I9: =_xlfn.COVARIANCE.P($M$22:$M$178,$U$22:$U$178)/_xlfn.VAR.P($U$22:$U$178) -> 0.2430946 | J9: =RSQ($M$22:$M$178,$U$22:$U$178) -> 0.00027444679
A10: 7 | B10: Link Snacks, Inc | F10: Private | H10: =N19 -> Kraft Heinz | I10: =_xlfn.COVARIANCE.P($O$22:$O$178,$U$22:$U$178)/_xlfn.VAR.P($U$22:$U$178) -> 0.79741099 | J10: =RSQ($O$22:$O$178,$U$22:$U$178) -> 0.24858799
A11: 8 | B11: Mondelēz International | E11: USA | F11: 80.11 | H11: =P19 -> Mondelez | I11: =_xlfn.COVARIANCE.P($Q$22:$Q$178,$U$22:$U$178)/_xlfn.VAR.P($U$22:$U$178) -> 0.75717638 | J11: =RSQ($Q$22:$Q$178,$U$22:$U$178) -> 0.51678726
A12: 9 | B12: Monster Beverage Corporation | E12: USA | F12: 40.9 | H12: =R19 -> Monster Beverage | I12: =_xlfn.COVARIANCE.P($S$22:$S$178,$U$22:$U$178)/_xlfn.VAR.P($U$22:$U$178) -> 1.0248664 | J12: =RSQ($S$22:$S$178,$U$22:$U$178) -> 0.48482729
A13: 10 | B13: Nestlé S.A. | E13: Europe | F13: 301
A14: 11 | B14: Red Bull GmbH | E14: Europe | F14: Private
B15: Source: 10K Dec 2019, Pg 9
A19: Date | B19: PepsiCo | D19: Coca Cola | F19: Campbell | H19: Conagra | J19: Kellogg | L19: Keurig Dr Pepper | N19: Kraft Heinz | P19: Mondelez | R19: Monster Beverage | T19: S&P 500
B20: Price | C20: % | D20: Price | E20: % | F20: Price | G20: % | H20: Price | I20: % | J20: Price | K20: % | L20: Price | M20: % | N20: Price | O20: % | P20: Price | Q20: % | R20: Price | S20: % | T20: Price | U20: %
A21: 43003 | B21: 101.79427 | D21: 40.75935 | F21: 42.145782 | H21: 31.164028 | J21: 56.095238 | L21: 13.319406 | N21: 67.020523 | P21: 37.858841 | R21: 55.25 | T21: 2519.3601
A22: 43010 | B22: 100.85334 | C22: =B22/B21-1 -> -0.0092434087 | D22: 41.194016 | E22: =D22/D21-1 -> 0.010664203 | F22: 41.839733 | G22: =F22/F21-1 -> -0.0072616757 | H22: 31.478077 | I22: =H22/H21-1 -> 0.010077292 | J22: 56.122223 | K22: =J22/J21-1 -> 0.00048105688 | L22: 13.287788 | M22: =L22/L21-1 -> -0.0023738296 | N22: 67.564987 | O22: =N22/N21-1 -> 0.0081238399 | P22: 38.505268 | Q22: =P22/P21-1 -> 0.017074664 | R22: 55.369999 | S22: =R22/R21-1 -> 0.0021719276 | T22: 2549.3301 | U22: =T22/T21-1 -> 0.011895866
A23: 43017 | B23: 102.88137 | C23: =B23/B22-1 -> 0.020108714 | D23: 41.818855 | E23: =D23/D22-1 -> 0.015168198 | F23: 41.569683 | G23: =F23/F22-1 -> -0.0064543911 | H23: 31.708986 | I23: =H23/H22-1 -> 0.0073355498 | J23: 55.72649 | K23: =J23/J22-1 -> -0.0070512709 | L23: 13.436839 | M23: =L23/L22-1 -> 0.011217142 | N23: 67.184715 | O23: =N23/N22-1 -> -0.0056282406 | P23: 39.020153 | Q23: =P23/P22-1 -> 0.013371807 | R23: 55.830002 | S23: =R23/R22-1 -> 0.0083078022 | T23: 2553.1699 | U23: =T23/T22-1 -> 0.0015062169
A24: 43024 | B24: 101.95872 | C24: =B24/B23-1 -> -0.0089681348 | D24: 41.999969 | E24: =D24/D23-1 -> 0.0043309172 | F24: 41.699726 | G24: =F24/F23-1 -> 0.0031283135 | H24: 31.321049 | I24: =H24/H23-1 -> -0.012234292 | J24: 55.267807 | K24: =J24/J23-1 -> -0.0082309688 | L24: 13.403714 | M24: =L24/L23-1 -> -0.0024652375 | N24: 66.294579 | O24: =N24/N23-1 -> -0.013249085 | P24: 38.402283 | Q24: =P24/P23-1 -> -0.015834638 | R24: 56.459999 | S24: =R24/R23-1 -> 0.011284202 | T24: 2575.21 | U24: =T24/T23-1 -> 0.0086324215
A25: 43031 | B25: 101.03604 | C25: =B25/B24-1 -> -0.0090495058 | D25: 41.719242 | E25: =D25/D24-1 -> -0.0066839811 | F25: 43.659088 | G25: =F25/F24-1 -> 0.046987407 | H25: 31.117847 | I25: =H25/H24-1 -> -0.0064877137 | J25: 54.197514 | K25: =J25/J24-1 -> -0.019365578 | L25: 12.909904 | M25: =L25/L24-1 -> -0.036841281 | N25: 66.804466 | O25: =N25/N24-1 -> 0.0076912322 | P25: 38.083977 | Q25: =P25/P24-1 -> -0.008288726 | R25: 56.75 | S25: =R25/R24-1 -> 0.0051363975 | T25: 2581.0701 | U25: =T25/T24-1 -> 0.0022755842
A26: 43038 | B26: 100.68892 | C26: =B26/B25-1 -> -0.0034356255 | D26: 41.628681 | E26: =D26/D25-1 -> -0.002170725 | F26: 42.162354 | G26: =F26/F25-1 -> -0.034282301 | H26: 31.321049 | I26: =H26/H25-1 -> 0.006530079 | J26: 55.72649 | K26: =J26/J25-1 -> 0.028211183 | L26: 12.890328 | M26: =L26/L25-1 -> -0.0015163552 | N26: 67.409416 | O26: =N26/N25-1 -> 0.0090555323 | P26: 38.355476 | Q26: =P26/P25-1 -> 0.0071289561 | R26: 57.669998 | S26: =R26/R25-1 -> 0.016211419 | T26: 2587.8401 | U26: =T26/T25-1 -> 0.0026229509
A27: 43045 | B27: 103.00014 | C27: =B27/B26-1 -> 0.022954045 | D27: 42.144855 | E27: =D27/D26-1 -> 0.01239948 | F27: 43.01503 | G27: =F27/F26-1 -> 0.020223634 | H27: 32.347137 | I27: =H27/H26-1 -> 0.032760333 | J27: 58.190834 | K27: =J27/J26-1 -> 0.044222128 | L27: 12.995719 | M27: =L27/L26-1 -> 0.008175975 | N27: 68.895882 | O27: =N27/N26-1 -> 0.022051311 | P27: 39.272938 | Q27: =P27/P26-1 -> 0.023919974 | R27: 61.16 | S27: =R27/R26-1 -> 0.06051677 | T27: 2582.3 | U27: =T27/T26-1 -> -0.0021407965
A28: 43052 | B28: 104.76324 | C28: =B28/B27-1 -> 0.017117453 | D28: 41.393238 | E28: =D28/D27-1 -> -0.017834134 | F28: 45.101383 | G28: =F28/F27-1 -> 0.048502884 | H28: 33.192993 | I28: =H28/H27-1 -> 0.026149331 | J28: 58.784435 | K28: =J28/J27-1 -> 0.010200936 | L28: 13.137236 | M28: =L28/L27-1 -> 0.010889509 | N28: 68.818108 | O28: =N28/N27-1 -> -0.0011288628 | P28: 39.600594 | Q28: =P28/P27-1 -> 0.0083430478 | R28: 62.169998 | S28: =R28/R27-1 -> 0.016514029 | T28: 2578.8501 | U28: =T28/T27-1 -> -0.0013359993
A29: 43059 | B29: 105.87775 | C29: =B29/B28-1 -> 0.010638369 | D29: 41.547176 | E29: =D29/D28-1 -> 0.0037189166 | F29: 41.763226 | G29: =F29/F28-1 -> -0.074014515 | H29: 32.960613 | I29: =H29/H28-1 -> -0.0070008752 | J29: 58.397701 | K29: =J29/J28-1 -> -0.0065788503 | L29: 13.031851 | M29: =L29/L28-1 -> -0.0080218548 | N29: 69.481682 | O29: =N29/N28-1 -> 0.0096424331 | P29: 39.460175 | Q29: =P29/P28-1 -> -0.0035458812 | R29: 61.75 | S29: =R29/R28-1 -> -0.006755638 | T29: 2602.4199 | U29: =T29/T28-1 -> 0.0091396642
A30: 43066 | B30: 106.68164 | C30: =B30/B29-1 -> 0.0075926625 | D30: 41.628681 | E30: =D30/D29-1 -> 0.0019617458 | F30: 44.647827 | G30: =F30/F29-1 -> 0.069070359 | H30: 34.828945 | I30: =H30/H29-1 -> 0.056683776 | J30: 59.351051 | K30: =J30/J29-1 -> 0.016325129 | L30: 13.588897 | M30: =L30/L29-1 -> 0.042744964 | N30: 70.744835 | O30: =N30/N29-1 -> 0.018179655 | P30: 40.181034 | Q30: =P30/P29-1 -> 0.018268013 | R30: 62.919998 | S30: =R30/R29-1 -> 0.018947336 | T30: 2642.22 | U30: =T30/T29-1 -> 0.015293477
A31: 43073 | B31: 107.22859 | C31: =B31/B30-1 -> 0.0051269459 | D31: 41.367416 | E31: =D31/D30-1 -> -0.0062760816 | F31: 44.402908 | G31: =F31/F30-1 -> -0.0054855749 | H31: 34.624447 | I31: =H31/H30-1 -> -0.0058714957 | J31: 60.324379 | K31: =J31/J30-1 -> 0.016399507 | L31: 14.174546 | M31: =L31/L30-1 -> 0.043097611 | N31: 68.366631 | O31: =N31/N30-1 -> -0.033616645 | P31: 39.928261 | Q31: =P31/P30-1 -> -0.0062908535 | R31: 63.220001 | S31: =R31/R30-1 -> 0.0047680071 | T31: 2651.5 | U31: =T31/T30-1 -> 0.0035122091
A32: 43080 | B32: 109.66622 | C32: =B32/B31-1 -> 0.022733023 | D32: 42.170834 | E32: =D32/D31-1 -> 0.019421518 | F32: 44.983456 | G32: =F32/F31-1 -> 0.013074549 | H32: 35.098495 | I32: =H32/H31-1 -> 0.013691136 | J32: 58.92802 | K32: =J32/J31-1 -> -0.023147507 | L32: 14.139918 | M32: =L32/L31-1 -> -0.0024429707 | N32: 69.290047 | O32: =N32/N31-1 -> 0.013506823 | P32: 40.611683 | Q32: =P32/P31-1 -> 0.017116248 | R32: 64.010002 | S32: =R32/R31-1 -> 0.012496061 | T32: 2675.8101 | U32: =T32/T31-1 -> 0.0091684175
A33: 43087 | B33: 109.09591 | C33: =B33/B32-1 -> -0.0052004436 | D33: 41.623047 | E33: =D33/D32-1 -> -0.012989712 | F33: 44.239632 | G33: =F33/F32-1 -> -0.016535501 | H33: 35.395947 | I33: =H33/H32-1 -> 0.0084747793 | J33: 61.747932 | K33: =J33/J32-1 -> 0.0478535 | L33: 14.560826 | M33: =L33/L32-1 -> 0.029767358 | N33: 68.157578 | O33: =N33/N32-1 -> -0.016343891 | P33: 40.592957 | Q33: =P33/P32-1 -> -0.00046109884 | R33: 63.77 | S33: =R33/R32-1 -> -0.0037494453 | T33: 2683.3401 | U33: =T33/T32-1 -> 0.0028141119
... A178: 44102 | B178: 137.16 | C178: =B178/B177-1 -> 0.027031081 | D178: 48.919998 | E178: =D178/D177-1 -> 0.0041050287 | F178: 47.674034 | G178: =F178/F177-1 -> 0.0096719532 | H178: 35.48 | I178: =H178/H177-1 -> 0.010250598 | J178: 63.439999 | K178: =J178/J177-1 -> 0.0057069909 | L178: 26.962664 | M178: =L178/L177-1 -> -0.027618286 | N178: 29.59 | O178: =N178/N177-1 -> 0.015791315 | P178: 56.167927 | Q178: =P178/P177-1 -> 0.0056979718 | R178: 79.790001 | S178: =R178/R177-1 -> 0.012691966 | T178: 3335.47 | U178: =T178/T177-1 -> 0.011220391

Sheet Debt Schedule
A1: PepsiCo Inc.
A2: ='PepsiCo-IS'!A2 -> (in USD million except per Share Data)
A3: Debt Schedule | B3: ='PepsiCo-CFS'!B3 -> 6 | C3: ='PepsiCo-CFS'!C3 -> 12 | D3: ='PepsiCo-CFS'!D3 -> 12 | E3: ='PepsiCo-CFS'!E3 -> 12 | F3: ='PepsiCo-CFS'!F3 -> 12 | G3: 12
B4: ='PepsiCo-CFS'!B4 -> 44196 | C4: ='PepsiCo-CFS'!C4 -> 44561 | D4: ='PepsiCo-CFS'!D4 -> 44926 | E4: ='PepsiCo-CFS'!E4 -> 45291 | F4: ='PepsiCo-CFS'!F4 -> 45657 | G4: =EOMONTH(F4,12) -> 46022
A6: Cash Before Debt | B6: ='PepsiCo-CFS'!B25 -> 4247.5556 | C6: ='PepsiCo-CFS'!C25 -> 4183.773 | D6: ='PepsiCo-CFS'!D25 -> 2792.5156 | E6: ='PepsiCo-CFS'!E25 -> 2873.1876 | F6: ='PepsiCo-CFS'!F25 -> 2937.039 | G6: What we got after yearly operations before debt repay and raise
A7: Add: Opening Cash Balance | B7: ='PepsiCo-BS'!E5 -> 8927 | C7: ='PepsiCo-BS'!F5 -> 7824.5556 | D7: ='PepsiCo-BS'!G5 -> 8732.3285 | E7: ='PepsiCo-BS'!H5 -> 7693.8441 | F7: ='PepsiCo-BS'!I5 -> 8295.0317 | G7: What we had before
A8: Less: Minimum Cash Required | B8: =-$G$8*'PepsiCo-IS'!J6 -> -1378.032 | C8: =-$G$8*'PepsiCo-IS'!K6 -> -1433.5658 | D8: =-$G$8*'PepsiCo-IS'!L6 -> -1492.1558 | E8: =-$G$8*'PepsiCo-IS'!M6 -> -1553.9942 | F8: =-$G$8*'PepsiCo-IS'!N6 -> -1619.2862 | G8: 0.02 | H8: of Sales | I8: Not mentioned here. Taken as average of 500 companies
A9: Cash Available for Debt | B9: =SUM(B6:B8) -> 11796.524 | C9: =SUM(C6:C8) -> 10574.763 | D9: =SUM(D6:D8) -> 10032.688 | E9: =SUM(E6:E8) -> 9013.0375 | F9: =SUM(F6:F8) -> 9612.7846
A10: Less: Mandatory Debt Repayments | B10: =-SUMIF($B$17:$B$33,"<="&B4,$I$17:$I$33) -> -2118 | C10: =-SUMIF($B$17:$B$33,"<="&C4,$I$17:$I$33)-SUM($B$10:B10) -> -3276 | D10: =-SUMIF($B$17:$B$33,"<="&D4,$I$17:$I$33)-SUM($B$10:C10) -> -3831 | E10: =-SUMIF($B$17:$B$33,"<="&E4,$I$17:$I$33)-SUM($B$10:D10) -> -2272 | F10: =-SUMIF($B$17:$B$33,"<="&F4,$I$17:$I$33)-SUM($B$10:E10) -> -2839 | G10: =-SUMIF($B$17:$B$33,"<="&G4,$I$17:$I$33)-SUM($B$10:F10) -> -20410
A11: Cash Available for Discretionery Sweep | B11: =SUM(B9:B10) -> 9678.5236 | C11: =SUM(C9:C10) -> 7298.7627 | D11: =SUM(D9:D10) -> 6201.6883 | E11: =SUM(E9:E10) -> 6741.0375 | F11: =SUM(F9:F10) -> 6773.7846
A12: Source: Calculations
A14: Individual debt raised and its details | M14: Interest Expenses
A15: Mandatory Debt | F15: Balance As on 31 Dec 2019 | G15: During 24 Weeks June 2020 | I15: Net Balance As on 13 June 2020 | M15: =B3 -> 6 | N15: =C3 -> 12 | O15: =D3 -> 12 | P15: =E3 -> 12 | Q15: =F3 -> 12
B16: Repayment Date | C16: Interest Rate | E16: Average Rate | G16: Raised | H16: Repaid | J16: Source | L16: 43995 | M16: =B4 -> 44196 | N16: =C4 -> 44561 | O16: =D4 -> 44926 | P16: =E4 -> 45291 | Q16: =F4 -> 45657
A17: 2020 Notes | B17: 44196 | C17: 0.027 | D17: 0.039 | E17: =AVERAGE(C17:D17) -> 0.033 | F17: 2840 | H17: 750 | I17: =F17+G17-H17 -> 2090 | J17: 10K Dec 2019, Pg 112 | M17: =IF(AND($B17<=M16,$B17>=L$16),($B17-L$16)*$I17*$E17/365,IF($B17<=L$16,0,$I17*$E17*M$15/12)) -> 37.98074 | N17: =IF(AND($B17<=N16,$B17>=M$16),($B17-M$16)*$I17*$E17/365,IF($B17<=M$16,0,$I17*$E17*N$15/12)) -> 0 | O17: =IF(AND($B17<=O16,$B17>=N$16),($B17-N$16)*$I17*$E17/365,IF($B17<=N$16,0,$I17*$E17*O$15/12)) -> 0 | P17: =IF(AND($B17<=P16,$B17>=O$16),($B17-O$16)*$I17*$E17/365,IF($B17<=O$16,0,$I17*$E17*P$15/12)) -> 0 | Q17: =IF(AND($B17<=Q16,$B17>=P$16),($B17-P$16)*$I17*$E17/365,IF($B17<=P$16,0,$I17*$E17*Q$15/12)) -> 0
A18: 2021 Notes | B18: 44561 | C18: 0.024 | D18: 0.031 | E18: =AVERAGE(C18:D18) -> 0.0275 | F18: 3276 | I18: =F18+G18-H18 -> 3276 | J18: 10K Dec 2019, Pg 112 | M18: =IF(AND($B18<=M17,$B18>=L$16),($B18-L$16)*$I18*$E18/365,IF($B18<=L$16,0,$I18*$E18*M$15/12)) -> 45.045 | N18: =IF(AND($B18<=N17,$B18>=M$16),($B18-M$16)*$I18*$E18/365,IF($B18<=M$16,0,$I18*$E18*N$15/12)) -> 90.09 | O18: =IF(AND($B18<=O17,$B18>=N$16),($B18-N$16)*$I18*$E18/365,IF($B18<=N$16,0,$I18*$E18*O$15/12)) -> 0 | P18: =IF(AND($B18<=P17,$B18>=O$16),($B18-O$16)*$I18*$E18/365,IF($B18<=O$16,0,$I18*$E18*P$15/12)) -> 0 | Q18: =IF(AND($B18<=Q17,$B18>=P$16),($B18-P$16)*$I18*$E18/365,IF($B18<=P$16,0,$I18*$E18*Q$15/12)) -> 0
A19: 2022 Notes | B19: 44926 | C19: 0.027 | D19: 0.028 | E19: =AVERAGE(C19:D19) -> 0.0275 | F19: 3831 | I19: =F19+G19-H19 -> 3831 | J19: 10K Dec 2019, Pg 112 | M19: =IF(AND($B19<=M18,$B19>=L$16),($B19-L$16)*$I19*$E19/365,IF($B19<=L$16,0,$I19*$E19*M$15/12)) -> 52.67625 | N19: =IF(AND($B19<=N18,$B19>=M$16),($B19-M$16)*$I19*$E19/365,IF($B19<=M$16,0,$I19*$E19*N$15/12)) -> 105.3525 | O19: =IF(AND($B19<=O18,$B19>=N$16),($B19-N$16)*$I19*$E19/365,IF($B19<=N$16,0,$I19*$E19*O$15/12)) -> 105.3525 | P19: =IF(AND($B19<=P18,$B19>=O$16),($B19-O$16)*$I19*$E19/365,IF($B19<=O$16,0,$I19*$E19*P$15/12)) -> 0 | Q19: =IF(AND($B19<=Q18,$B19>=P$16),($B19-P$16)*$I19*$E19/365,IF($B19<=P$16,0,$I19*$E19*Q$15/12)) -> 0
A20: 2023 Notes | B20: 45291 | C20: 0.028 | D20: 0.029 | E20: =AVERAGE(C20:D20) -> 0.0285 | F20: 1272 | I20: =F20+G20-H20 -> 1272 | J20: 10K Dec 2019, Pg 112 | M20: =IF(AND($B20<=M19,$B20>=L$16),($B20-L$16)*$I20*$E20/365,IF($B20<=L$16,0,$I20*$E20*M$15/12)) -> 18.126 | N20: =IF(AND($B20<=N19,$B20>=M$16),($B20-M$16)*$I20*$E20/365,IF($B20<=M$16,0,$I20*$E20*N$15/12)) -> 36.252 | O20: =IF(AND($B20<=O19,$B20>=N$16),($B20-N$16)*$I20*$E20/365,IF($B20<=N$16,0,$I20*$E20*O$15/12)) -> 36.252 | P20: =IF(AND($B20<=P19,$B20>=O$16),($B20-O$16)*$I20*$E20/365,IF($B20<=O$16,0,$I20*$E20*P$15/12)) -> 36.252 | Q20: =IF(AND($B20<=Q19,$B20>=P$16),($B20-P$16)*$I20*$E20/365,IF($B20<=P$16,0,$I20*$E20*Q$15/12)) -> 0
A21: 2024 Notes | B21: 45657 | C21: 0.034 | D21: 0.032 | E21: =AVERAGE(C21:D21) -> 0.033 | F21: 1839 | I21: =F21+G21-H21 -> 1839 | J21: 10K Dec 2019, Pg 112 | M21: =IF(AND($B21<=M20,$B21>=L$16),($B21-L$16)*$I21*$E21/365,IF($B21<=L$16,0,$I21*$E21*M$15/12)) -> 30.3435 | N21: =IF(AND($B21<=N20,$B21>=M$16),($B21-M$16)*$I21*$E21/365,IF($B21<=M$16,0,$I21*$E21*N$15/12)) -> 60.687 | O21: =IF(AND($B21<=O20,$B21>=N$16),($B21-N$16)*$I21*$E21/365,IF($B21<=N$16,0,$I21*$E21*O$15/12)) -> 60.687 | P21: =IF(AND($B21<=P20,$B21>=O$16),($B21-O$16)*$I21*$E21/365,IF($B21<=O$16,0,$I21*$E21*P$15/12)) -> 60.687 | Q21: =IF(AND($B21<=Q20,$B21>=P$16),($B21-P$16)*$I21*$E21/365,IF($B21<=P$16,0,$I21*$E21*Q$15/12)) -> 60.687
A22: 2025-2049 Notes | B22: 46022 | C22: 0.034 | D22: 0.037 | E22: =AVERAGE(C22:D22) -> 0.0355 | F22: 18910 | I22: =F22+G22-H22 -> 18910 | J22: 10K Dec 2019, Pg 112 | M22: =IF(AND($B22<=M21,$B22>=L$16),($B22-L$16)*$I22*$E22/365,IF($B22<=L$16,0,$I22*$E22*M$15/12)) -> 335.6525 | N22: =IF(AND($B22<=N21,$B22>=M$16),($B22-M$16)*$I22*$E22/365,IF($B22<=M$16,0,$I22*$E22*N$15/12)) -> 671.305 | O22: =IF(AND($B22<=O21,$B22>=N$16),($B22-N$16)*$I22*$E22/365,IF($B22<=N$16,0,$I22*$E22*O$15/12)) -> 671.305 | P22: =IF(AND($B22<=P21,$B22>=O$16),($B22-O$16)*$I22*$E22/365,IF($B22<=O$16,0,$I22*$E22*P$15/12)) -> 671.305 | Q22: =IF(AND($B22<=Q21,$B22>=P$16),($B22-P$16)*$I22*$E22/365,IF($B22<=P$16,0,$I22*$E22*Q$15/12)) -> 671.305
A23: 2019-2026 Notes | B23: 44196 | C23: 0.013 | D23: =C23 -> 0.013 | E23: =AVERAGE(C23:D23) -> 0.013 | F23: 28 | I23: =F23+G23-H23 -> 28 | J23: 10K Dec 2019, Pg 112 | M23: =IF(AND($B23<=M22,$B23>=L$16),($B23-L$16)*$I23*$E23/365,IF($B23<=L$16,0,$I23*$E23*M$15/12)) -> 0.182 | N23: =IF(AND($B23<=N22,$B23>=M$16),($B23-M$16)*$I23*$E23/365,IF($B23<=M$16,0,$I23*$E23*N$15/12)) -> 0 | O23: =IF(AND($B23<=O22,$B23>=N$16),($B23-N$16)*$I23*$E23/365,IF($B23<=N$16,0,$I23*$E23*O$15/12)) -> 0 | P23: =IF(AND($B23<=P22,$B23>=O$16),($B23-O$16)*$I23*$E23/365,IF($B23<=O$16,0,$I23*$E23*P$15/12)) -> 0 | Q23: =IF(AND($B23<=Q22,$B23>=P$16),($B23-P$16)*$I23*$E23/365,IF($B23<=P$16,0,$I23*$E23*Q$15/12)) -> 0
A24: New Notes March 2025 | B24: 45747 | C24: 0.0225 | D24: 0.0225 | E24: =AVERAGE(C24:D24) -> 0.0225 | G24: 1500 | I24: =F24+G24-H24 -> 1500 | J24: 10Q June 2020, Pg 19 | M24: =IF(AND($B24<=M23,$B24>=L$16),($B24-L$16)*$I24*$E24/365,IF($B24<=L$16,0,$I24*$E24*M$15/12)) -> 16.875 | N24: =IF(AND($B24<=N23,$B24>=M$16),($B24-M$16)*$I24*$E24/365,IF($B24<=M$16,0,$I24*$E24*N$15/12)) -> 33.75 | O24: =IF(AND($B24<=O23,$B24>=N$16),($B24-N$16)*$I24*$E24/365,IF($B24<=N$16,0,$I24*$E24*O$15/12)) -> 33.75 | P24: =IF(AND($B24<=P23,$B24>=O$16),($B24-O$16)*$I24*$E24/365,IF($B24<=O$16,0,$I24*$E24*P$15/12)) -> 33.75 | Q24: =IF(AND($B24<=Q23,$B24>=P$16),($B24-P$16)*$I24*$E24/365,IF($B24<=P$16,0,$I24*$E24*Q$15/12)) -> 33.75
A25: New Notes March 2027 | B25: 46477 | C25: 0.02625 | D25: 0.02625 | E25: =AVERAGE(C25:D25) -> 0.02625 | G25: 500 | I25: =F25+G25-H25 -> 500 | J25: 10Q June 2020, Pg 19 | M25: =IF(AND($B25<=M24,$B25>=L$16),($B25-L$16)*$I25*$E25/365,IF($B25<=L$16,0,$I25*$E25*M$15/12)) -> 6.5625 | N25: =IF(AND($B25<=N24,$B25>=M$16),($B25-M$16)*$I25*$E25/365,IF($B25<=M$16,0,$I25*$E25*N$15/12)) -> 13.125 | O25: =IF(AND($B25<=O24,$B25>=N$16),($B25-N$16)*$I25*$E25/365,IF($B25<=N$16,0,$I25*$E25*O$15/12)) -> 13.125 | P25: =IF(AND($B25<=P24,$B25>=O$16),($B25-O$16)*$I25*$E25/365,IF($B25<=O$16,0,$I25*$E25*P$15/12)) -> 13.125 | Q25: =IF(AND($B25<=Q24,$B25>=P$16),($B25-P$16)*$I25*$E25/365,IF($B25<=P$16,0,$I25*$E25*Q$15/12)) -> 13.125
A26: New Notes March 2030 | B26: 47573 | C26: 0.0275 | D26: 0.0275 | E26: =AVERAGE(C26:D26) -> 0.0275 | G26: 1500 | I26: =F26+G26-H26 -> 1500 | J26: 10Q June 2020, Pg 19 | M26: =IF(AND($B26<=M25,$B26>=L$16),($B26-L$16)*$I26*$E26/365,IF($B26<=L$16,0,$I26*$E26*M$15/12)) -> 20.625 | N26: =IF(AND($B26<=N25,$B26>=M$16),($B26-M$16)*$I26*$E26/365,IF($B26<=M$16,0,$I26*$E26*N$15/12)) -> 41.25 | O26: =IF(AND($B26<=O25,$B26>=N$16),($B26-N$16)*$I26*$E26/365,IF($B26<=N$16,0,$I26*$E26*O$15/12)) -> 41.25 | P26: =IF(AND($B26<=P25,$B26>=O$16),($B26-O$16)*$I26*$E26/365,IF($B26<=O$16,0,$I26*$E26*P$15/12)) -> 41.25 | Q26: =IF(AND($B26<=Q25,$B26>=P$16),($B26-P$16)*$I26*$E26/365,IF($B26<=P$16,0,$I26*$E26*Q$15/12)) -> 41.25
A27: New Notes March 2040 | B27: 51226 | C27: 0.035 | D27: 0.035 | E27: =AVERAGE(C27:D27) -> 0.035 | G27: 750 | I27: =F27+G27-H27 -> 750 | J27: 10Q June 2020, Pg 19 | M27: =IF(AND($B27<=M26,$B27>=L$16),($B27-L$16)*$I27*$E27/365,IF($B27<=L$16,0,$I27*$E27*M$15/12)) -> 13.125 | N27: =IF(AND($B27<=N26,$B27>=M$16),($B27-M$16)*$I27*$E27/365,IF($B27<=M$16,0,$I27*$E27*N$15/12)) -> 26.25 | O27: =IF(AND($B27<=O26,$B27>=N$16),($B27-N$16)*$I27*$E27/365,IF($B27<=N$16,0,$I27*$E27*O$15/12)) -> 26.25 | P27: =IF(AND($B27<=P26,$B27>=O$16),($B27-O$16)*$I27*$E27/365,IF($B27<=O$16,0,$I27*$E27*P$15/12)) -> 26.25 | Q27: =IF(AND($B27<=Q26,$B27>=P$16),($B27-P$16)*$I27*$E27/365,IF($B27<=P$16,0,$I27*$E27*Q$15/12)) -> 26.25
A28: New Notes March 2050 | B28: 54878 | C28: 0.03625 | D28: 0.03625 | E28: =AVERAGE(C28:D28) -> 0.03625 | G28: 1500 | I28: =F28+G28-H28 -> 1500 | J28: 10Q June 2020, Pg 19 | M28: =IF(AND($B28<=M27,$B28>=L$16),($B28-L$16)*$I28*$E28/365,IF($B28<=L$16,0,$I28*$E28*M$15/12)) -> 27.1875 | N28: =IF(AND($B28<=N27,$B28>=M$16),($B28-M$16)*$I28*$E28/365,IF($B28<=M$16,0,$I28*$E28*N$15/12)) -> 54.375 | O28: =IF(AND($B28<=O27,$B28>=N$16),($B28-N$16)*$I28*$E28/365,IF($B28<=N$16,0,$I28*$E28*O$15/12)) -> 54.375 | P28: =IF(AND($B28<=P27,$B28>=O$16),($B28-O$16)*$I28*$E28/365,IF($B28<=O$16,0,$I28*$E28*P$15/12)) -> 54.375 | Q28: =IF(AND($B28<=Q27,$B28>=P$16),($B28-P$16)*$I28*$E28/365,IF($B28<=P$16,0,$I28*$E28*Q$15/12)) -> 54.375
A29: New Notes March 2060 | B29: 58531 | C29: 0.03875 | D29: 0.03875 | E29: =AVERAGE(C29:D29) -> 0.03875 | G29: 750 | I29: =F29+G29-H29 -> 750 | J29: 10Q June 2020, Pg 19 | M29: =IF(AND($B29<=M28,$B29>=L$16),($B29-L$16)*$I29*$E29/365,IF($B29<=L$16,0,$I29*$E29*M$15/12)) -> 14.53125 | N29: =IF(AND($B29<=N28,$B29>=M$16),($B29-M$16)*$I29*$E29/365,IF($B29<=M$16,0,$I29*$E29*N$15/12)) -> 29.0625 | O29: =IF(AND($B29<=O28,$B29>=N$16),($B29-N$16)*$I29*$E29/365,IF($B29<=N$16,0,$I29*$E29*O$15/12)) -> 29.0625 | P29: =IF(AND($B29<=P28,$B29>=O$16),($B29-O$16)*$I29*$E29/365,IF($B29<=O$16,0,$I29*$E29*P$15/12)) -> 29.0625 | Q29: =IF(AND($B29<=Q28,$B29>=P$16),($B29-P$16)*$I29*$E29/365,IF($B29<=P$16,0,$I29*$E29*Q$15/12)) -> 29.0625
A30: New Notes May 2023 | B30: 45077 | C30: 0.0075 | D30: 0.0075 | E30: =AVERAGE(C30:D30) -> 0.0075 | G30: 1000 | I30: =F30+G30-H30 -> 1000 | J30: 10Q June 2020, Pg 19 | M30: =IF(AND($B30<=M29,$B30>=L$16),($B30-L$16)*$I30*$E30/365,IF($B30<=L$16,0,$I30*$E30*M$15/12)) -> 3.75 | N30: =IF(AND($B30<=N29,$B30>=M$16),($B30-M$16)*$I30*$E30/365,IF($B30<=M$16,0,$I30*$E30*N$15/12)) -> 7.5 | O30: =IF(AND($B30<=O29,$B30>=N$16),($B30-N$16)*$I30*$E30/365,IF($B30<=N$16,0,$I30*$E30*O$15/12)) -> 7.5 | P30: =IF(AND($B30<=P29,$B30>=O$16),($B30-O$16)*$I30*$E30/365,IF($B30<=O$16,0,$I30*$E30*P$15/12)) -> 7.5 | Q30: =IF(AND($B30<=Q29,$B30>=P$16),($B30-P$16)*$I30*$E30/365,IF($B30<=P$16,0,$I30*$E30*Q$15/12)) -> 0
A31: New Notes May 2030 | B31: 47634 | C31: 0.01625 | D31: 0.01625 | E31: =AVERAGE(C31:D31) -> 0.01625 | G31: 1000 | I31: =F31+G31-H31 -> 1000 | J31: 10Q June 2020, Pg 19 | M31: =IF(AND($B31<=M30,$B31>=L$16),($B31-L$16)*$I31*$E31/365,IF($B31<=L$16,0,$I31*$E31*M$15/12)) -> 8.125 | N31: =IF(AND($B31<=N30,$B31>=M$16),($B31-M$16)*$I31*$E31/365,IF($B31<=M$16,0,$I31*$E31*N$15/12)) -> 16.25 | O31: =IF(AND($B31<=O30,$B31>=N$16),($B31-N$16)*$I31*$E31/365,IF($B31<=N$16,0,$I31*$E31*O$15/12)) -> 16.25 | P31: =IF(AND($B31<=P30,$B31>=O$16),($B31-O$16)*$I31*$E31/365,IF($B31<=O$16,0,$I31*$E31*P$15/12)) -> 16.25 | Q31: =IF(AND($B31<=Q30,$B31>=P$16),($B31-P$16)*$I31*$E31/365,IF($B31<=P$16,0,$I31*$E31*Q$15/12)) -> 16.25
A32: New Notes May 2024 | B32: 45443 | C32: 0.0025 | D32: 0.0025 | E32: =AVERAGE(C32:D32) -> 0.0025 | G32: 1000 | I32: =F32+G32-H32 -> 1000 | J32: 10Q June 2020, Pg 19 | M32: =IF(AND($B32<=M31,$B32>=L$16),($B32-L$16)*$I32*$E32/365,IF($B32<=L$16,0,$I32*$E32*M$15/12)) -> 1.25 | N32: =IF(AND($B32<=N31,$B32>=M$16),($B32-M$16)*$I32*$E32/365,IF($B32<=M$16,0,$I32*$E32*N$15/12)) -> 2.5 | O32: =IF(AND($B32<=O31,$B32>=N$16),($B32-N$16)*$I32*$E32/365,IF($B32<=N$16,0,$I32*$E32*O$15/12)) -> 2.5 | P32: =IF(AND($B32<=P31,$B32>=O$16),($B32-O$16)*$I32*$E32/365,IF($B32<=O$16,0,$I32*$E32*P$15/12)) -> 2.5 | Q32: =IF(AND($B32<=Q31,$B32>=P$16),($B32-P$16)*$I32*$E32/365,IF($B32<=P$16,0,$I32*$E32*Q$15/12)) -> 2.5
A33: New Notes May 2028 | B33: 46904 | C33: 0.005 | D33: 0.005 | E33: =AVERAGE(C33:D33) -> 0.005 | G33: 1000 | I33: =F33+G33-H33 -> 1000 | J33: 10Q June 2020, Pg 19 | M33: =IF(AND($B33<=M32,$B33>=L$16),($B33-L$16)*$I33*$E33/365,IF($B33<=L$16,0,$I33*$E33*M$15/12)) -> 2.5 | N33: =IF(AND($B33<=N32,$B33>=M$16),($B33-M$16)*$I33*$E33/365,IF($B33<=M$16,0,$I33*$E33*N$15/12)) -> 5 | O33: =IF(AND($B33<=O32,$B33>=N$16),($B33-N$16)*$I33*$E33/365,IF($B33<=N$16,0,$I33*$E33*O$15/12)) -> 5 | P33: =IF(AND($B33<=P32,$B33>=O$16),($B33-O$16)*$I33*$E33/365,IF($B33<=O$16,0,$I33*$E33*P$15/12)) -> 5 | Q33: =IF(AND($B33<=Q32,$B33>=P$16),($B33-P$16)*$I33*$E33/365,IF($B33<=P$16,0,$I33*$E33*Q$15/12)) -> 5
A35: Total Mandatory Debt | E35: =AVERAGE(E17:E33) -> 0.024441176 | F35: =SUM(F17:F34) -> 31996 | G35: =SUM(G17:G34) -> 10500 | H35: =SUM(H17:H34) -> 750 | I35: =SUM(I17:I34) -> 41746 | M35: =SUM(M17:M34) -> 634.53724 | N35: =SUM(N17:N34) -> 1192.749 | O35: =SUM(O17:O34) -> 1102.659 | P35: =SUM(P17:P34) -> 997.3065 | Q35: =SUM(Q17:Q34) -> 953.5545
A37: Total Debt (Discretionery + Mandatory) | F37: ='PepsiCo-BS'!D23+'PepsiCo-BS'!D27 -> 32068 | I37: ='PepsiCo-BS'!E23+'PepsiCo-BS'!E27 -> 44978
A39: Discretionary Debt (Balance) | F39: =F37-F35 -> 72 | I39: =I37-I35 -> 3232
A42: Discretionary Debt Schedule | B42: Amount need to be repaid with choice of time
B43: =B3 -> 6 | C43: =C3 -> 12 | D43: =D3 -> 12 | E43: =E3 -> 12 | F43: =F3 -> 12
B44: =B4 -> 44196 | C44: =C4 -> 44561 | D44: =D4 -> 44926 | E44: =E4 -> 45291 | F44: =F4 -> 45657
A45: Opening Balance | B45: =I39 -> 3232 | C45: =B48 -> 0 | D45: =C48 -> 0 | E45: =D48 -> 0 | F45: =E48 -> 0
A46: Add: Debt Raised | B46: =IF(B11<0,-B11,0) -> 0 | C46: =IF(C11<0,-C11,0) -> 0 | D46: =IF(D11<0,-D11,0) -> 0 | E46: =IF(E11<0,-E11,0) -> 0 | F46: =IF(F11<0,-F11,0) -> 0
A47: Less: Debt Repaid | B47: =IF(B11>11,MIN(B45,B11),0) -> 3232 | C47: =IF(C11>11,MIN(C45,C11),0) -> 0 | D47: =IF(D11>11,MIN(D45,D11),0) -> 0 | E47: =IF(E11>11,MIN(E45,E11),0) -> 0 | F47: =IF(F11>11,MIN(F45,F11),0) -> 0
...

Sheet Fixed Assets Schedule
A1: PepsiCo Inc.
A2: ='PepsiCo-IS'!A2 -> (in USD million except per Share Data)
A3: Property, Plant & Equipment | B3: ='PepsiCo-IS'!E3 -> 12 | C3: ='PepsiCo-IS'!F3 -> 12 | D3: ='PepsiCo-IS'!G3 -> 12 | E3: ='PepsiCo-IS'!H3 -> 6 | G3: ='PepsiCo-IS'!I3 -> 6 | H3: ='PepsiCo-IS'!K3 -> 12 | I3: ='PepsiCo-IS'!L3 -> 12 | J3: ='PepsiCo-IS'!M3 -> 12 | K3: ='PepsiCo-IS'!N3 -> 12
B4: ='PepsiCo-IS'!E4 -> 43100 | C4: 43465 | D4: 43830 | E4: June-30-2020 | G4: ='PepsiCo-IS'!I4 -> 44196 | H4: ='PepsiCo-IS'!K4 -> 44561 | I4: ='PepsiCo-IS'!L4 -> 44926 | J4: ='PepsiCo-IS'!M4 -> 45291 | K4: ='PepsiCo-IS'!N4 -> 45657
A5: Opening Balance-WDV | B5: 16591 | C5: =B9 -> 17240 | D5: =C9 -> 17589 | E5: =D9 -> 19305 | G5: =E9 -> 19187 | H5: =G9 -> 20303.375 | I5: =H9 -> 19839.788 | J5: =I9 -> 20650.643 | K5: =J9 -> 21506.453
A6: Add: Net Addition during the Period | B6: =B7-B5 -> 2950 | C6: =C7-C5 -> 2679 | D6: =D7-D5 -> 4067 | E6: =E7-E5 -> 966.63076 | G6: =G7-G5 -> 2348.5197 | H6: =H7-H5 -> 2100.0133 | I6: =I7-I5 -> 3479.2286 | J6: =J7-J5 -> 3634.7676 | K6: =K7-K5 -> 3799.3231
A7: Total Depreciable Assets During the Year | B7: =B9+B8 -> 19541 | C7: =C9+C8 -> 19919 | D7: =D9+D8 -> 21656 | E7: =E9+E8 -> 20271.631 | G7: =('PepsiCo-IS'!J6/'Fixed Assets Schedule'!$G$13) -> 21535.52 | H7: =('PepsiCo-IS'!K6/'Fixed Assets Schedule'!$G$13) -> 22403.388 | I7: =('PepsiCo-IS'!L6/'Fixed Assets Schedule'!$G$13) -> 23319.017 | J7: =('PepsiCo-IS'!M6/'Fixed Assets Schedule'!$G$13) -> 24285.411 | K7: =('PepsiCo-IS'!N6/'Fixed Assets Schedule'!$G$13) -> 25305.776
A8: Less: Depreciation during the year | B8: =B20 -> 2301 | C8: =C20 -> 2330 | D8: =D20 -> 2351 | E8: =E20 -> 1084.6308 | G8: =G7*$G$15/2 -> 1232.1451 | H8: =H7*$G$15 -> 2563.5995 | I8: =I7*$G$15 -> 2668.3741 | J8: =J7*$G$15 -> 2778.9577 | K8: =K7*$G$15 -> 2895.7172 | L8: Linked to IS after splitting
A9: Closing Balance-WDV | B9: ='PepsiCo-BS'!B13 -> 17240 | C9: ='PepsiCo-BS'!C13 -> 17589 | D9: ='PepsiCo-BS'!D13 -> 19305 | E9: ='PepsiCo-BS'!E13 -> 19187 | G9: =G7-G8 -> 20303.375 | H9: =H7-H8 -> 19839.788 | I9: =I7-I8 -> 20650.643 | J9: =J7-J8 -> 21506.453 | K9: =K7-K8 -> 22410.059
A10: Source | B10: 10K Dec'17, Pg 84 | C10: 10K Dec'19, Pg 79 | E10: 10Q June'20, Pg 8 | G10: Calculation
E12: 6 Monthly | G12: Yearly
A13: PPE Turnover Ratio | B13: ='PepsiCo-IS'!E6/'Fixed Assets Schedule'!B7 -> 3.2508572 | C13: ='PepsiCo-IS'!F6/'Fixed Assets Schedule'!C7 -> 3.2461971 | D13: ='PepsiCo-IS'!G6/'Fixed Assets Schedule'!D7 -> 3.1012652 | E13: ='PepsiCo-IS'!H6/'Fixed Assets Schedule'!E7 -> 1.4713172 | G13: =AVERAGE(B13:D13) -> 3.1994398
A15: Depreciation Rate | B15: =B8/B7 -> 0.11775242 | C15: =C8/C7 -> 0.11697374 | D15: =D8/D7 -> 0.10856114 | E15: =E8/E7 -> 0.05350486 | G15: =AVERAGE(B15:D15) -> 0.1144291
A18: Depreciation Exp | B18: ='PepsiCo-IS'!E11 -> 2107 | C18: ='PepsiCo-IS'!F11 -> 2144 | D18: ='PepsiCo-IS'!G11 -> 2196 | E18: ='PepsiCo-IS'!H11 -> 1013.1217 | F18: =AVERAGE(B21:E21) -> 0.92600043 | G18: =G20*$F$18 -> 1140.9669 | H18: =H20*$F$18 -> 2373.8943 | I18: =I20*$F$18 -> 2470.9156 | J18: =J20*$F$18 -> 2573.316 | K18: =K20*$F$18 -> 2681.4353 | L18: Splitting
A19: Corporate Depreciation and Amort | B19: ='PepsiCo-IS'!E19 -> 194 | C19: ='PepsiCo-IS'!F19 -> 186 | D19: ='PepsiCo-IS'!G19 -> 155 | E19: ='PepsiCo-IS'!H19 -> 71.509046 | G19: =G20-G18 -> 91.178205 | H19: =H20-H18 -> 189.70526 | I19: =I20-I18 -> 197.45854 | J19: =J20-J18 -> 205.64167 | K19: =K20-K18 -> 214.28182
B20: =SUM(B18:B19) -> 2301 | C20: =SUM(C18:C19) -> 2330 | D20: =SUM(D18:D19) -> 2351 | E20: =SUM(E18:E19) -> 1084.6308 | G20: =G8 -> 1232.1451 | H20: =H8 -> 2563.5995 | I20: =I8 -> 2668.3741 | J20: =J8 -> 2778.9577 | K20: =K8 -> 2895.7172
B21: =B18/B20 -> 0.91568883 | C21: =C18/C20 -> 0.92017167 | D21: =D18/D20 -> 0.93407061 | E21: =E18/E20 -> 0.93407061
A22: Amortizable Intangible Assets, net | B22: =B3 -> 12 | C22: =C3 -> 12 | D22: =D3 -> 12 | E22: =E3 -> 6 | G22: =G3 -> 6 | H22: =H3 -> 12 | I22: =I3 -> 12 | J22: =J3 -> 12 | K22: =K3 -> 12
B23: =B4 -> 43100 | C23: =C4 -> 43465 | D23: =D4 -> 43830 | E23: =E4 -> June-30-2020 | G23: =G4 -> 44196 | H23: =H4 -> 44561 | I23: =I4 -> 44926 | J23: =J4 -> 45291 | K23: =K4 -> 45657
A24: Opening Balance-WDV | B24: 1237 | C24: =B28 -> 1268 | D24: =C28 -> 1644 | E24: =D28 -> 1433 | G24: =E28 -> 1465 | H24: =G28 -> 1429.6742 | I24: =H28 -> 1360.7262 | J24: =I28 -> 1295.1033 | K24: =J28 -> 1232.6452
A25: Add: Net Addition during the Period | B25: =B26-B24 -> 99 | C25: =C26-C24 -> 445 | D25: =D26-D24 -> -130 | E25: =E26-E24 -> 69.369243 | G25: 0 | H25: 0 | I25: 0 | J25: 0 | K25: 0
A26: Total Amortizable Assets During the Year | B26: =B27+B28 -> 1336 | C26: =C27+C28 -> 1713 | D26: =D27+D28 -> 1514 | E26: =E27+E28 -> 1502.3692 | G26: =G24-G25 -> 1465 | H26: =H24-H25 -> 1429.6742 | I26: =I24-I25 -> 1360.7262 | J26: =J24-J25 -> 1295.1033 | K26: =K24-K25 -> 1232.6452
A27: Less: Amortisation during the year | B27: ='PepsiCo-IS'!E20 -> 68 | C27: ='PepsiCo-IS'!F20 -> 69 | D27: ='PepsiCo-IS'!G20 -> 81 | E27: ='PepsiCo-IS'!H20 -> 37.369243 | G27: =G26*$G$32/2 -> 35.325807 | H27: =H26*$G$32 -> 68.94798 | I27: =I26*$G$32 -> 65.62287 | J27: =J26*$G$32 -> 62.458118 | K27: =K26*$G$32 -> 59.44599
A28: Closing Balance-WDV | B28: ='PepsiCo-BS'!B14 -> 1268 | C28: ='PepsiCo-BS'!C14 -> 1644 | D28: ='PepsiCo-BS'!D14 -> 1433 | E28: ='PepsiCo-BS'!E14 -> 1465 | G28: =G26-G27 -> 1429.6742 | H28: =H26-H27 -> 1360.7262 | I28: =I26-I27 -> 1295.1033 | J28: =J26-J27 -> 1232.6452 | K28: =K26-K27 -> 1173.1992
A29: Source | B29: 10K Dec'17, Pg 84 | C29: 10K Dec'19, Pg 79 | E29: 10Q June'20, Pg 8 | G29: Calculation
E31: 6 Monthly
A32: Amortisation Rate | B32: =B27/B26 -> 0.050898204 | C32: =C27/C26 -> 0.04028021 | D32: =D27/D26 -> 0.053500661 | E32: =E27/E26 -> 0.024873541 | G32: =AVERAGE(B32:D32) -> 0.048226358

Sheet PepsiCo-BS
A1: PepsiCo Inc.
A2: ='PepsiCo-IS'!A2 -> (in USD million except per Share Data)
A3: Balance Sheet as of: | B3: ='PepsiCo-IS'!E4 -> 43100 | C3: ='PepsiCo-IS'!F4 -> 43465 | D3: ='PepsiCo-IS'!G4 -> 43830 | E3: ='PepsiCo-IS'!H4 -> 43995 | F3: ='PepsiCo-IS'!J4 -> 44196 | G3: ='PepsiCo-IS'!K4 -> 44561 | H3: ='PepsiCo-IS'!L4 -> 44926 | I3: ='PepsiCo-IS'!M4 -> 45291 | J3: ='PepsiCo-IS'!N4 -> 45657
A4: ASSETS
A5: Cash And Equivalents | B5: 10610 | C5: 8721 | D5: 5509 | E5: 8927 | F5: ='PepsiCo-CFS'!B35 -> 7824.5556 | G5: ='PepsiCo-CFS'!C35 -> 8732.3285 | H5: ='PepsiCo-CFS'!D35 -> 7693.8441 | I5: ='PepsiCo-CFS'!E35 -> 8295.0317 | J5: ='PepsiCo-CFS'!F35 -> 8393.0707
A6: Short Term Investments | B6: 8900 | C6: 272 | D6: 229 | E6: 196 | F6: =E6 -> 196 | G6: =F6 -> 196 | H6: =G6 -> 196 | I6: =H6 -> 196 | J6: =I6 -> 196
A7: Restricted Cash | B7: 0 | C7: 1997 | D7: 0 | E7: 0 | F7: 0 | G7: 0 | H7: 0 | I7: 0 | J7: 0
A8: Accounts and Notes Receivable | B8: 7024 | C8: 7142 | D8: 7822 | E8: 8780 | F8: =F76 -> 7751.2008 | G8: =G76 -> 8063.5694 | H8: =H76 -> 8393.1284 | I8: =I76 -> 8740.9589 | J8: =J76 -> 9108.2153
A9: Inventories | B9: 2947 | C9: 3128 | D9: 3338 | E9: 4314 | F9: =F78 -> 3233.8369 | G9: =G78 -> 3430.3254 | H9: =H78 -> 3570.5232 | I9: =I78 -> 3718.4939 | J9: =J78 -> 3874.7286
A10: Prepaid expenses and other current assets | B10: 1546 | C10: 633 | D10: 747 | E10: 972 | F10: =F80 -> 1039.241 | G10: =G80 -> 1081.1218 | H10: =H80 -> 1125.3073 | I10: =I80 -> 1171.9426 | J10: =J80 -> 1221.1825
A11: Total Current Assets | B11: =SUM(B5:B10) -> 31027 | C11: =SUM(C5:C10) -> 21893 | D11: =SUM(D5:D10) -> 17645 | E11: =SUM(E5:E10) -> 23189 | F11: =SUM(F5:F10) -> 20044.834 | G11: =SUM(G5:G10) -> 21503.345 | H11: =SUM(H5:H10) -> 20978.803 | I11: =SUM(I5:I10) -> 22122.427 | J11: =SUM(J5:J10) -> 22793.197
A13: Net Property, Plant & Equipment | B13: 17240 | C13: 17589 | D13: 19305 | E13: 19187 | F13: ='Fixed Assets Schedule'!G9 -> 20303.375 | G13: ='Fixed Assets Schedule'!H9 -> 19839.788 | H13: ='Fixed Assets Schedule'!I9 -> 20650.643 | I13: ='Fixed Assets Schedule'!J9 -> 21506.453 | J13: ='Fixed Assets Schedule'!K9 -> 22410.059
A14: Amortizable Intangible Assets, net | B14: 1268 | C14: 1644 | D14: 1433 | E14: 1465 | F14: ='Fixed Assets Schedule'!G28 -> 1429.6742 | G14: ='Fixed Assets Schedule'!H28 -> 1360.7262 | H14: ='Fixed Assets Schedule'!I28 -> 1295.1033 | I14: ='Fixed Assets Schedule'!J28 -> 1232.6452 | J14: ='Fixed Assets Schedule'!K28 -> 1173.1992
A15: Goodwill | B15: 14744 | C15: 14808 | D15: 15501 | E15: 17845 | F15: =E15 -> 17845 | G15: =F15 -> 17845 | H15: =G15 -> 17845 | I15: =H15 -> 17845 | J15: =I15 -> 17845
A16: Other indefinite-lived intangible assets | B16: 12570 | C16: 14181 | D16: 14610 | E16: 17530 | F16: =E16 -> 17530 | G16: =F16 -> 17530 | H16: =G16 -> 17530 | I16: =H16 -> 17530 | J16: =I16 -> 17530
A17: Investments in Noncontrolled Affiliates | B17: 2042 | C17: 2409 | D17: 2683 | E17: 2715 | F17: =E17 -> 2715 | G17: =F17 -> 2715 | H17: =G17 -> 2715 | I17: =H17 -> 2715 | J17: =I17 -> 2715
A18: Deferred Income Taxes | B18: 0 | C18: 4364 | D18: 4359 | E18: 4351 | F18: =E18 -> 4351 | G18: =F18 -> 4351 | H18: =G18 -> 4351 | I18: =H18 -> 4351 | J18: =I18 -> 4351
A19: Other Assets | B19: 913 | C19: 760 | D19: 3011 | E19: 3243 | F19: =E19 -> 3243 | G19: =F19 -> 3243 | H19: =G19 -> 3243 | I19: =H19 -> 3243 | J19: =I19 -> 3243
A20: Total Assets | B20: =SUM(B11:B19) -> 79804 | C20: =SUM(C11:C19) -> 77648 | D20: =SUM(D11:D19) -> 78547 | E20: =SUM(E11:E19) -> 89525 | F20: =SUM(F13:F19,F11) -> 87461.883 | G20: =SUM(G13:G19,G11) -> 88387.86 | H20: =SUM(H13:H19,H11) -> 88608.549 | I20: =SUM(I13:I19,I11) -> 90545.525 | J20: =SUM(J13:J19,J11) -> 92060.455
A22: LIABILITIES
A23: Short-term debt obligations | B23: 5485 | C23: 4026 | D23: 2920 | E23: 6607 | F23: ='Debt Schedule'!B72 -> 3276 | G23: ='Debt Schedule'!C72 -> 3831 | H23: ='Debt Schedule'!D72 -> 2272 | I23: ='Debt Schedule'!E72 -> 2839 | J23: ='Debt Schedule'!F72 -> 20410
A24: Accounts payable and other current liabilities | B24: 15017 | C24: 18112 | D24: 17541 | E24: 17220 | F24: =F65 -> 18096.39 | G24: =G65 -> 19021.791 | H24: =H65 -> 19682.08 | I24: =I65 -> 20378.977 | J24: =J65 -> 21114.795
A25: Total Current Liabilities | B25: =SUM(B23:B24) -> 20502 | C25: =SUM(C23:C24) -> 22138 | D25: =SUM(D23:D24) -> 20461 | E25: =SUM(E23:E24) -> 23827 | F25: =SUM(F23:F24) -> 21372.39 | G25: =SUM(G23:G24) -> 22852.791 | H25: =SUM(H23:H24) -> 21954.08 | I25: =SUM(I23:I24) -> 23217.977 | J25: =SUM(J23:J24) -> 41524.795
A27: Long-Term Debt Obligations | B27: 33796 | C27: 28295 | D27: 29148 | E27: 38371 | F27: ='Debt Schedule'!B73 -> 36352 | G27: ='Debt Schedule'!C73 -> 32521 | H27: ='Debt Schedule'!D73 -> 30249 | I27: ='Debt Schedule'!E73 -> 27410 | J27: ='Debt Schedule'!F73 -> 7000
A28: Deferred Income Taxes | B28: 3242 | C28: 3499 | D28: 4091 | E28: 4203 | F28: =E28 -> 4203 | G28: =F28 -> 4203 | H28: =G28 -> 4203 | I28: =H28 -> 4203 | J28: =I28 -> 4203 | K28: Same
A29: Other Liabilities | B29: 11283 | C29: 9114 | D29: 9979 | E29: 10537 | F29: =E29 -> 10537 | G29: =F29 -> 10537 | H29: =G29 -> 10537 | I29: =H29 -> 10537 | J29: =I29 -> 10537 | K29: Same
A30: Total Liabilities | B30: =SUM(B25:B29) -> 68823 | C30: =SUM(C25:C29) -> 63046 | D30: =SUM(D25:D29) -> 63679 | E30: =SUM(E25:E29) -> 76938 | F30: =SUM(F27:F29,F25) -> 72464.39 | G30: =SUM(G27:G29,G25) -> 70113.791 | H30: =SUM(H27:H29,H25) -> 66943.08 | I30: =SUM(I27:I29,I25) -> 65367.977 | J30: =SUM(J27:J29,J25) -> 63264.795
A32: Preferred Stock, no par value | B32: 41
A33: Repurchased Preferred Stock | B33: -197
A35: Common Stock | B35: 24 | C35: 23 | D35: 23 | E35: 23 | F35: =E35 -> 23 | G35: =F35 -> 23 | H35: =G35 -> 23 | I35: =H35 -> 23 | J35: =I35 -> 23 | K35: same
A36: Capital in excess of par value | B36: 3996 | C36: 3953 | D36: 3886 | E36: 3772 | F36: =E36+'PepsiCo-CFS'!B9 -> 3904.1863 | G36: =F36+'PepsiCo-CFS'!C9 -> 4182.0954 | H36: =G36+'PepsiCo-CFS'!D9 -> 4471.3017 | I36: =H36+'PepsiCo-CFS'!E9 -> 4772.4348 | J36: =I36+'PepsiCo-CFS'!F9 -> 5086.1643 | K36: same
A37: Retained Earnings | B37: 52839 | C37: 59947 | D37: 61946 | E37: 62145 | F37: =E37+'PepsiCo-IS'!I46+'PepsiCo-CFS'!B24 -> 64389.262 | G37: =F37+'PepsiCo-IS'!K46+'PepsiCo-CFS'!C24 -> 67335.473 | H37: =G37+'PepsiCo-IS'!L46+'PepsiCo-CFS'!D24 -> 70383.401 | I37: =H37+'PepsiCo-IS'!M46+'PepsiCo-CFS'!E24 -> 73538.178 | J37: =I37+'PepsiCo-IS'!N46+'PepsiCo-CFS'!F24 -> 76784.757
A38: Accumulated other comprehensive loss | B38: -13057 | C38: -15119 | D38: -14300 | E38: -15778 | F38: =E38 -> -15778 | G38: =F38 -> -15778 | H38: =G38 -> -15778 | I38: =H38 -> -15778 | J38: =I38 -> -15778 | K38: same
